[2024-07-21T08:43:54.112+0000] {local_task_job_runner.py:120} INFO - ::group::Pre task execution logs
[2024-07-21T08:43:54.124+0000] {taskinstance.py:2076} INFO - Dependencies all met for dep_context=non-requeueable deps ti=<TaskInstance: churn_model_DAG.data_processing manual__2024-07-21T08:32:51.568366+00:00 [queued]>
[2024-07-21T08:43:54.204+0000] {taskinstance.py:2076} INFO - Dependencies all met for dep_context=requeueable deps ti=<TaskInstance: churn_model_DAG.data_processing manual__2024-07-21T08:32:51.568366+00:00 [queued]>
[2024-07-21T08:43:54.205+0000] {taskinstance.py:2306} INFO - Starting attempt 4 of 4
[2024-07-21T08:43:54.210+0000] {taskinstance.py:2330} INFO - Executing <Task(PythonOperator): data_processing> on 2024-07-21 08:32:51.568366+00:00
[2024-07-21T08:43:54.215+0000] {warnings.py:112} WARNING - /home/***/.local/lib/python3.12/site-packages/***/task/task_runner/standard_task_runner.py:62: DeprecationWarning: This process (pid=1806) is multi-threaded, use of fork() may lead to deadlocks in the child.
  pid = os.fork()

[2024-07-21T08:43:54.217+0000] {standard_task_runner.py:64} INFO - Started process 1815 to run task
[2024-07-21T08:43:54.216+0000] {standard_task_runner.py:90} INFO - Running: ['***', 'tasks', 'run', 'churn_model_DAG', 'data_processing', 'manual__2024-07-21T08:32:51.568366+00:00', '--job-id', '451', '--raw', '--subdir', 'DAGS_FOLDER/model_pipeline_DAG.py', '--cfg-path', '/tmp/tmpiimdyy1p']
[2024-07-21T08:43:54.218+0000] {standard_task_runner.py:91} INFO - Job 451: Subtask data_processing
[2024-07-21T08:43:54.255+0000] {task_command.py:426} INFO - Running <TaskInstance: churn_model_DAG.data_processing manual__2024-07-21T08:32:51.568366+00:00 [running]> on host 6e10856c4017
[2024-07-21T08:43:54.291+0000] {taskinstance.py:2648} INFO - Exporting env vars: AIRFLOW_CTX_DAG_OWNER='***' AIRFLOW_CTX_DAG_ID='churn_model_DAG' AIRFLOW_CTX_TASK_ID='data_processing' AIRFLOW_CTX_EXECUTION_DATE='2024-07-21T08:32:51.568366+00:00' AIRFLOW_CTX_TRY_NUMBER='4' AIRFLOW_CTX_DAG_RUN_ID='manual__2024-07-21T08:32:51.568366+00:00'
[2024-07-21T08:43:54.291+0000] {taskinstance.py:430} INFO - ::endgroup::
[2024-07-21T08:43:54.300+0000] {taskinstance.py:441} INFO - ::group::Post task execution logs
[2024-07-21T08:43:54.300+0000] {taskinstance.py:2905} ERROR - Task failed with exception
Traceback (most recent call last):
  File "/home/airflow/.local/lib/python3.12/site-packages/airflow/models/taskinstance.py", line 465, in _execute_task
    result = _execute_callable(context=context, **execute_callable_kwargs)
             ^^^^^^^^^^^^^^^^^^^^^^^^^^^^^^^^^^^^^^^^^^^^^^^^^^^^^^^^^^^^^
  File "/home/airflow/.local/lib/python3.12/site-packages/airflow/models/taskinstance.py", line 432, in _execute_callable
    return execute_callable(context=context, **execute_callable_kwargs)
           ^^^^^^^^^^^^^^^^^^^^^^^^^^^^^^^^^^^^^^^^^^^^^^^^^^^^^^^^^^^^
  File "/home/airflow/.local/lib/python3.12/site-packages/airflow/models/baseoperator.py", line 401, in wrapper
    return func(self, *args, **kwargs)
           ^^^^^^^^^^^^^^^^^^^^^^^^^^^
  File "/home/airflow/.local/lib/python3.12/site-packages/airflow/operators/python.py", line 235, in execute
    return_value = self.execute_callable()
                   ^^^^^^^^^^^^^^^^^^^^^^^
  File "/home/airflow/.local/lib/python3.12/site-packages/airflow/operators/python.py", line 252, in execute_callable
    return self.python_callable(*self.op_args, **self.op_kwargs)
           ^^^^^^^^^^^^^^^^^^^^^^^^^^^^^^^^^^^^^^^^^^^^^^^^^^^^^
  File "/opt/airflow/dags/model_pipeline_DAG.py", line 30, in run_data_processor
    data_processor.clean_data()
  File "/opt/airflow/dags/data_cleaning_OOP.py", line 100, in clean_data
    data = pd.read_csv(input_path, delimiter=';', decimal=',')
           ^^^^^^^^^^^^^^^^^^^^^^^^^^^^^^^^^^^^^^^^^^^^^^^^^^^
  File "/home/airflow/.local/lib/python3.12/site-packages/pandas/io/parsers/readers.py", line 948, in read_csv
    return _read(filepath_or_buffer, kwds)
           ^^^^^^^^^^^^^^^^^^^^^^^^^^^^^^^
  File "/home/airflow/.local/lib/python3.12/site-packages/pandas/io/parsers/readers.py", line 611, in _read
    parser = TextFileReader(filepath_or_buffer, **kwds)
             ^^^^^^^^^^^^^^^^^^^^^^^^^^^^^^^^^^^^^^^^^^
  File "/home/airflow/.local/lib/python3.12/site-packages/pandas/io/parsers/readers.py", line 1448, in __init__
    self._engine = self._make_engine(f, self.engine)
                   ^^^^^^^^^^^^^^^^^^^^^^^^^^^^^^^^^
  File "/home/airflow/.local/lib/python3.12/site-packages/pandas/io/parsers/readers.py", line 1705, in _make_engine
    self.handles = get_handle(
                   ^^^^^^^^^^^
  File "/home/airflow/.local/lib/python3.12/site-packages/pandas/io/common.py", line 863, in get_handle
    handle = open(
             ^^^^^
FileNotFoundError: [Errno 2] No such file or directory: '/opt/airflow/data/dataset.csv'
[2024-07-21T08:43:54.306+0000] {taskinstance.py:1206} INFO - Marking task as FAILED. dag_id=churn_model_DAG, task_id=data_processing, run_id=manual__2024-07-21T08:32:51.568366+00:00, execution_date=20240721T083251, start_date=20240721T084354, end_date=20240721T084354
[2024-07-21T08:43:54.311+0000] {standard_task_runner.py:110} ERROR - Failed to execute job 451 for task data_processing ([Errno 2] No such file or directory: '/opt/airflow/data/dataset.csv'; 1815)
[2024-07-21T08:43:54.317+0000] {local_task_job_runner.py:243} INFO - Task exited with return code 1
[2024-07-21T08:43:54.328+0000] {taskinstance.py:3503} INFO - 0 downstream tasks scheduled from follow-on schedule check
[2024-07-21T08:43:54.329+0000] {local_task_job_runner.py:222} INFO - ::endgroup::
