[2024-07-19T11:24:59.006+0000] {local_task_job_runner.py:120} INFO - ::group::Pre task execution logs
[2024-07-19T11:24:59.023+0000] {taskinstance.py:2076} INFO - Dependencies all met for dep_context=non-requeueable deps ti=<TaskInstance: random_forest_training.train_model manual__2024-07-19T11:19:52.608110+00:00 [queued]>
[2024-07-19T11:24:59.030+0000] {taskinstance.py:2076} INFO - Dependencies all met for dep_context=requeueable deps ti=<TaskInstance: random_forest_training.train_model manual__2024-07-19T11:19:52.608110+00:00 [queued]>
[2024-07-19T11:24:59.031+0000] {taskinstance.py:2306} INFO - Starting attempt 2 of 2
[2024-07-19T11:24:59.172+0000] {taskinstance.py:2330} INFO - Executing <Task(PythonOperator): train_model> on 2024-07-19 11:19:52.608110+00:00
[2024-07-19T11:24:59.179+0000] {warnings.py:112} WARNING - /home/***/.local/lib/python3.12/site-packages/***/task/task_runner/standard_task_runner.py:62: DeprecationWarning: This process (pid=286) is multi-threaded, use of fork() may lead to deadlocks in the child.
  pid = os.fork()

[2024-07-19T11:24:59.180+0000] {standard_task_runner.py:64} INFO - Started process 295 to run task
[2024-07-19T11:24:59.180+0000] {standard_task_runner.py:90} INFO - Running: ['***', 'tasks', 'run', 'random_forest_training', 'train_model', 'manual__2024-07-19T11:19:52.608110+00:00', '--job-id', '41', '--raw', '--subdir', 'DAGS_FOLDER/model_train_dag.py', '--cfg-path', '/tmp/tmp0kz59czn']
[2024-07-19T11:24:59.182+0000] {standard_task_runner.py:91} INFO - Job 41: Subtask train_model
[2024-07-19T11:24:59.209+0000] {task_command.py:426} INFO - Running <TaskInstance: random_forest_training.train_model manual__2024-07-19T11:19:52.608110+00:00 [running]> on host 6e10856c4017
[2024-07-19T11:24:59.243+0000] {taskinstance.py:2648} INFO - Exporting env vars: AIRFLOW_CTX_DAG_OWNER='***' AIRFLOW_CTX_DAG_ID='random_forest_training' AIRFLOW_CTX_TASK_ID='train_model' AIRFLOW_CTX_EXECUTION_DATE='2024-07-19T11:19:52.608110+00:00' AIRFLOW_CTX_TRY_NUMBER='2' AIRFLOW_CTX_DAG_RUN_ID='manual__2024-07-19T11:19:52.608110+00:00'
[2024-07-19T11:24:59.244+0000] {taskinstance.py:430} INFO - ::endgroup::
[2024-07-19T11:24:59.252+0000] {taskinstance.py:441} INFO - ::group::Post task execution logs
[2024-07-19T11:24:59.252+0000] {taskinstance.py:2905} ERROR - Task failed with exception
Traceback (most recent call last):
  File "/home/airflow/.local/lib/python3.12/site-packages/airflow/models/taskinstance.py", line 465, in _execute_task
    result = _execute_callable(context=context, **execute_callable_kwargs)
             ^^^^^^^^^^^^^^^^^^^^^^^^^^^^^^^^^^^^^^^^^^^^^^^^^^^^^^^^^^^^^
  File "/home/airflow/.local/lib/python3.12/site-packages/airflow/models/taskinstance.py", line 432, in _execute_callable
    return execute_callable(context=context, **execute_callable_kwargs)
           ^^^^^^^^^^^^^^^^^^^^^^^^^^^^^^^^^^^^^^^^^^^^^^^^^^^^^^^^^^^^
  File "/home/airflow/.local/lib/python3.12/site-packages/airflow/models/baseoperator.py", line 401, in wrapper
    return func(self, *args, **kwargs)
           ^^^^^^^^^^^^^^^^^^^^^^^^^^^
  File "/home/airflow/.local/lib/python3.12/site-packages/airflow/operators/python.py", line 235, in execute
    return_value = self.execute_callable()
                   ^^^^^^^^^^^^^^^^^^^^^^^
  File "/home/airflow/.local/lib/python3.12/site-packages/airflow/operators/python.py", line 252, in execute_callable
    return self.python_callable(*self.op_args, **self.op_kwargs)
           ^^^^^^^^^^^^^^^^^^^^^^^^^^^^^^^^^^^^^^^^^^^^^^^^^^^^^
  File "/opt/airflow/dags/model_train_dag.py", line 16, in train_model
    data = pd.read_csv('/path/to/data/data_clean.csv', delimiter=',', decimal='.')
           ^^^^^^^^^^^^^^^^^^^^^^^^^^^^^^^^^^^^^^^^^^^^^^^^^^^^^^^^^^^^^^^^^^^^^^^
  File "/home/airflow/.local/lib/python3.12/site-packages/pandas/io/parsers/readers.py", line 948, in read_csv
    return _read(filepath_or_buffer, kwds)
           ^^^^^^^^^^^^^^^^^^^^^^^^^^^^^^^
  File "/home/airflow/.local/lib/python3.12/site-packages/pandas/io/parsers/readers.py", line 611, in _read
    parser = TextFileReader(filepath_or_buffer, **kwds)
             ^^^^^^^^^^^^^^^^^^^^^^^^^^^^^^^^^^^^^^^^^^
  File "/home/airflow/.local/lib/python3.12/site-packages/pandas/io/parsers/readers.py", line 1448, in __init__
    self._engine = self._make_engine(f, self.engine)
                   ^^^^^^^^^^^^^^^^^^^^^^^^^^^^^^^^^
  File "/home/airflow/.local/lib/python3.12/site-packages/pandas/io/parsers/readers.py", line 1705, in _make_engine
    self.handles = get_handle(
                   ^^^^^^^^^^^
  File "/home/airflow/.local/lib/python3.12/site-packages/pandas/io/common.py", line 863, in get_handle
    handle = open(
             ^^^^^
FileNotFoundError: [Errno 2] No such file or directory: '/path/to/data/data_clean.csv'
[2024-07-19T11:24:59.260+0000] {taskinstance.py:1206} INFO - Marking task as FAILED. dag_id=random_forest_training, task_id=train_model, run_id=manual__2024-07-19T11:19:52.608110+00:00, execution_date=20240719T111952, start_date=20240719T112459, end_date=20240719T112459
[2024-07-19T11:24:59.266+0000] {standard_task_runner.py:110} ERROR - Failed to execute job 41 for task train_model ([Errno 2] No such file or directory: '/path/to/data/data_clean.csv'; 295)
[2024-07-19T11:24:59.279+0000] {local_task_job_runner.py:243} INFO - Task exited with return code 1
[2024-07-19T11:24:59.288+0000] {taskinstance.py:3503} INFO - 0 downstream tasks scheduled from follow-on schedule check
[2024-07-19T11:24:59.289+0000] {local_task_job_runner.py:222} INFO - ::endgroup::
