[2024-07-20T01:54:36.144+0000] {local_task_job_runner.py:120} INFO - ::group::Pre task execution logs
[2024-07-20T01:54:36.164+0000] {taskinstance.py:2076} INFO - Dependencies all met for dep_context=non-requeueable deps ti=<TaskInstance: data_cleaning.clean_data scheduled__2024-07-19T00:00:00+00:00 [queued]>
[2024-07-20T01:54:36.171+0000] {taskinstance.py:2076} INFO - Dependencies all met for dep_context=requeueable deps ti=<TaskInstance: data_cleaning.clean_data scheduled__2024-07-19T00:00:00+00:00 [queued]>
[2024-07-20T01:54:36.172+0000] {taskinstance.py:2306} INFO - Starting attempt 2 of 2
[2024-07-20T01:54:36.179+0000] {taskinstance.py:2330} INFO - Executing <Task(PythonOperator): clean_data> on 2024-07-19 00:00:00+00:00
[2024-07-20T01:54:36.190+0000] {warnings.py:112} WARNING - /home/***/.local/lib/python3.12/site-packages/***/task/task_runner/standard_task_runner.py:62: DeprecationWarning: This process (pid=2051) is multi-threaded, use of fork() may lead to deadlocks in the child.
  pid = os.fork()

[2024-07-20T01:54:36.191+0000] {standard_task_runner.py:64} INFO - Started process 2069 to run task
[2024-07-20T01:54:36.191+0000] {standard_task_runner.py:90} INFO - Running: ['***', 'tasks', 'run', 'data_cleaning', 'clean_data', 'scheduled__2024-07-19T00:00:00+00:00', '--job-id', '431', '--raw', '--subdir', 'DAGS_FOLDER/data_cleaning_dag.py', '--cfg-path', '/tmp/tmpvu98s_a6']
[2024-07-20T01:54:36.193+0000] {standard_task_runner.py:91} INFO - Job 431: Subtask clean_data
[2024-07-20T01:54:36.230+0000] {task_command.py:426} INFO - Running <TaskInstance: data_cleaning.clean_data scheduled__2024-07-19T00:00:00+00:00 [running]> on host 6e10856c4017
[2024-07-20T01:54:36.277+0000] {taskinstance.py:2648} INFO - Exporting env vars: AIRFLOW_CTX_DAG_OWNER='***' AIRFLOW_CTX_DAG_ID='data_cleaning' AIRFLOW_CTX_TASK_ID='clean_data' AIRFLOW_CTX_EXECUTION_DATE='2024-07-19T00:00:00+00:00' AIRFLOW_CTX_TRY_NUMBER='2' AIRFLOW_CTX_DAG_RUN_ID='scheduled__2024-07-19T00:00:00+00:00'
[2024-07-20T01:54:36.278+0000] {taskinstance.py:430} INFO - ::endgroup::
[2024-07-20T01:54:36.289+0000] {taskinstance.py:441} INFO - ::group::Post task execution logs
[2024-07-20T01:54:36.289+0000] {taskinstance.py:2905} ERROR - Task failed with exception
Traceback (most recent call last):
  File "/home/airflow/.local/lib/python3.12/site-packages/airflow/models/taskinstance.py", line 465, in _execute_task
    result = _execute_callable(context=context, **execute_callable_kwargs)
             ^^^^^^^^^^^^^^^^^^^^^^^^^^^^^^^^^^^^^^^^^^^^^^^^^^^^^^^^^^^^^
  File "/home/airflow/.local/lib/python3.12/site-packages/airflow/models/taskinstance.py", line 432, in _execute_callable
    return execute_callable(context=context, **execute_callable_kwargs)
           ^^^^^^^^^^^^^^^^^^^^^^^^^^^^^^^^^^^^^^^^^^^^^^^^^^^^^^^^^^^^
  File "/home/airflow/.local/lib/python3.12/site-packages/airflow/models/baseoperator.py", line 401, in wrapper
    return func(self, *args, **kwargs)
           ^^^^^^^^^^^^^^^^^^^^^^^^^^^
  File "/home/airflow/.local/lib/python3.12/site-packages/airflow/operators/python.py", line 235, in execute
    return_value = self.execute_callable()
                   ^^^^^^^^^^^^^^^^^^^^^^^
  File "/home/airflow/.local/lib/python3.12/site-packages/airflow/operators/python.py", line 252, in execute_callable
    return self.python_callable(*self.op_args, **self.op_kwargs)
           ^^^^^^^^^^^^^^^^^^^^^^^^^^^^^^^^^^^^^^^^^^^^^^^^^^^^^
  File "/opt/airflow/dags/data_cleaning_dag.py", line 111, in main
    data = pd.read_csv(data_path, delimiter=';', decimal=',')
           ^^^^^^^^^^^^^^^^^^^^^^^^^^^^^^^^^^^^^^^^^^^^^^^^^^
  File "/home/airflow/.local/lib/python3.12/site-packages/pandas/io/parsers/readers.py", line 948, in read_csv
    return _read(filepath_or_buffer, kwds)
           ^^^^^^^^^^^^^^^^^^^^^^^^^^^^^^^
  File "/home/airflow/.local/lib/python3.12/site-packages/pandas/io/parsers/readers.py", line 611, in _read
    parser = TextFileReader(filepath_or_buffer, **kwds)
             ^^^^^^^^^^^^^^^^^^^^^^^^^^^^^^^^^^^^^^^^^^
  File "/home/airflow/.local/lib/python3.12/site-packages/pandas/io/parsers/readers.py", line 1448, in __init__
    self._engine = self._make_engine(f, self.engine)
                   ^^^^^^^^^^^^^^^^^^^^^^^^^^^^^^^^^
  File "/home/airflow/.local/lib/python3.12/site-packages/pandas/io/parsers/readers.py", line 1705, in _make_engine
    self.handles = get_handle(
                   ^^^^^^^^^^^
  File "/home/airflow/.local/lib/python3.12/site-packages/pandas/io/common.py", line 863, in get_handle
    handle = open(
             ^^^^^
FileNotFoundError: [Errno 2] No such file or directory: '../data/dataset.csv'
[2024-07-20T01:54:36.297+0000] {taskinstance.py:1206} INFO - Marking task as FAILED. dag_id=data_cleaning, task_id=clean_data, run_id=scheduled__2024-07-19T00:00:00+00:00, execution_date=20240719T000000, start_date=20240720T015436, end_date=20240720T015436
[2024-07-20T01:54:36.303+0000] {standard_task_runner.py:110} ERROR - Failed to execute job 431 for task clean_data ([Errno 2] No such file or directory: '../data/dataset.csv'; 2069)
[2024-07-20T01:54:36.332+0000] {local_task_job_runner.py:243} INFO - Task exited with return code 1
[2024-07-20T01:54:36.341+0000] {taskinstance.py:3503} INFO - 0 downstream tasks scheduled from follow-on schedule check
[2024-07-20T01:54:36.342+0000] {local_task_job_runner.py:222} INFO - ::endgroup::
