[2024-07-21T08:53:08.226+0000] {local_task_job_runner.py:120} INFO - ::group::Pre task execution logs
[2024-07-21T08:53:08.280+0000] {taskinstance.py:2076} INFO - Dependencies all met for dep_context=non-requeueable deps ti=<TaskInstance: churn_model_DAG.model_training manual__2024-07-21T08:52:56.825766+00:00 [queued]>
[2024-07-21T08:53:08.586+0000] {taskinstance.py:2076} INFO - Dependencies all met for dep_context=requeueable deps ti=<TaskInstance: churn_model_DAG.model_training manual__2024-07-21T08:52:56.825766+00:00 [queued]>
[2024-07-21T08:53:08.588+0000] {taskinstance.py:2306} INFO - Starting attempt 1 of 2
[2024-07-21T08:53:08.612+0000] {taskinstance.py:2330} INFO - Executing <Task(PythonOperator): model_training> on 2024-07-21 08:52:56.825766+00:00
[2024-07-21T08:53:08.668+0000] {warnings.py:112} WARNING - /home/***/.local/lib/python3.12/site-packages/***/task/task_runner/standard_task_runner.py:62: DeprecationWarning: This process (pid=293) is multi-threaded, use of fork() may lead to deadlocks in the child.
  pid = os.fork()

[2024-07-21T08:53:08.670+0000] {standard_task_runner.py:64} INFO - Started process 317 to run task
[2024-07-21T08:53:08.670+0000] {standard_task_runner.py:90} INFO - Running: ['***', 'tasks', 'run', 'churn_model_DAG', 'model_training', 'manual__2024-07-21T08:52:56.825766+00:00', '--job-id', '459', '--raw', '--subdir', 'DAGS_FOLDER/model_pipeline_DAG.py', '--cfg-path', '/tmp/tmpe3sdqwvp']
[2024-07-21T08:53:08.674+0000] {standard_task_runner.py:91} INFO - Job 459: Subtask model_training
[2024-07-21T08:53:08.707+0000] {task_command.py:426} INFO - Running <TaskInstance: churn_model_DAG.model_training manual__2024-07-21T08:52:56.825766+00:00 [running]> on host 6e10856c4017
[2024-07-21T08:53:08.751+0000] {taskinstance.py:2648} INFO - Exporting env vars: AIRFLOW_CTX_DAG_OWNER='***' AIRFLOW_CTX_DAG_ID='churn_model_DAG' AIRFLOW_CTX_TASK_ID='model_training' AIRFLOW_CTX_EXECUTION_DATE='2024-07-21T08:52:56.825766+00:00' AIRFLOW_CTX_TRY_NUMBER='1' AIRFLOW_CTX_DAG_RUN_ID='manual__2024-07-21T08:52:56.825766+00:00'
[2024-07-21T08:53:08.753+0000] {taskinstance.py:430} INFO - ::endgroup::
[2024-07-21T08:53:08.993+0000] {taskinstance.py:441} INFO - ::group::Post task execution logs
[2024-07-21T08:53:08.994+0000] {taskinstance.py:2905} ERROR - Task failed with exception
Traceback (most recent call last):
  File "/home/airflow/.local/lib/python3.12/site-packages/airflow/models/taskinstance.py", line 465, in _execute_task
    result = _execute_callable(context=context, **execute_callable_kwargs)
             ^^^^^^^^^^^^^^^^^^^^^^^^^^^^^^^^^^^^^^^^^^^^^^^^^^^^^^^^^^^^^
  File "/home/airflow/.local/lib/python3.12/site-packages/airflow/models/taskinstance.py", line 432, in _execute_callable
    return execute_callable(context=context, **execute_callable_kwargs)
           ^^^^^^^^^^^^^^^^^^^^^^^^^^^^^^^^^^^^^^^^^^^^^^^^^^^^^^^^^^^^
  File "/home/airflow/.local/lib/python3.12/site-packages/airflow/models/baseoperator.py", line 401, in wrapper
    return func(self, *args, **kwargs)
           ^^^^^^^^^^^^^^^^^^^^^^^^^^^
  File "/home/airflow/.local/lib/python3.12/site-packages/airflow/operators/python.py", line 235, in execute
    return_value = self.execute_callable()
                   ^^^^^^^^^^^^^^^^^^^^^^^
  File "/home/airflow/.local/lib/python3.12/site-packages/airflow/operators/python.py", line 252, in execute_callable
    return self.python_callable(*self.op_args, **self.op_kwargs)
           ^^^^^^^^^^^^^^^^^^^^^^^^^^^^^^^^^^^^^^^^^^^^^^^^^^^^^
  File "/opt/airflow/dags/model_pipeline_DAG.py", line 34, in run_model_training
    trainer.train_and_evaluate()
  File "/opt/airflow/dags/model_train.py", line 62, in train_and_evaluate
    X_train, X_test, y_train, y_test = self.load_data()
                                       ^^^^^^^^^^^^^^^^
  File "/opt/airflow/dags/model_train.py", line 29, in load_data
    X = data.drop(['churn'], axis=1)
        ^^^^^^^^^^^^^^^^^^^^^^^^^^^^
  File "/home/airflow/.local/lib/python3.12/site-packages/pandas/core/frame.py", line 5344, in drop
    return super().drop(
           ^^^^^^^^^^^^^
  File "/home/airflow/.local/lib/python3.12/site-packages/pandas/core/generic.py", line 4711, in drop
    obj = obj._drop_axis(labels, axis, level=level, errors=errors)
          ^^^^^^^^^^^^^^^^^^^^^^^^^^^^^^^^^^^^^^^^^^^^^^^^^^^^^^^^
  File "/home/airflow/.local/lib/python3.12/site-packages/pandas/core/generic.py", line 4753, in _drop_axis
    new_axis = axis.drop(labels, errors=errors)
               ^^^^^^^^^^^^^^^^^^^^^^^^^^^^^^^^
  File "/home/airflow/.local/lib/python3.12/site-packages/pandas/core/indexes/base.py", line 7000, in drop
    raise KeyError(f"{labels[mask].tolist()} not found in axis")
KeyError: "['churn'] not found in axis"
[2024-07-21T08:53:09.008+0000] {taskinstance.py:1206} INFO - Marking task as UP_FOR_RETRY. dag_id=churn_model_DAG, task_id=model_training, run_id=manual__2024-07-21T08:52:56.825766+00:00, execution_date=20240721T085256, start_date=20240721T085308, end_date=20240721T085309
[2024-07-21T08:53:09.016+0000] {standard_task_runner.py:110} ERROR - Failed to execute job 459 for task model_training ("['churn'] not found in axis"; 317)
[2024-07-21T08:53:09.063+0000] {local_task_job_runner.py:243} INFO - Task exited with return code 1
[2024-07-21T08:53:09.081+0000] {taskinstance.py:3503} INFO - 0 downstream tasks scheduled from follow-on schedule check
[2024-07-21T08:53:09.082+0000] {local_task_job_runner.py:222} INFO - ::endgroup::
