[2024-07-19T11:45:44.327+0000] {local_task_job_runner.py:120} INFO - ::group::Pre task execution logs
[2024-07-19T11:45:44.624+0000] {taskinstance.py:2076} INFO - Dependencies all met for dep_context=non-requeueable deps ti=<TaskInstance: data_cleaning.clean_data scheduled__2024-07-18T00:00:00+00:00 [queued]>
[2024-07-19T11:45:44.639+0000] {taskinstance.py:2076} INFO - Dependencies all met for dep_context=requeueable deps ti=<TaskInstance: data_cleaning.clean_data scheduled__2024-07-18T00:00:00+00:00 [queued]>
[2024-07-19T11:45:44.640+0000] {taskinstance.py:2306} INFO - Starting attempt 1 of 2
[2024-07-19T11:45:44.679+0000] {taskinstance.py:2330} INFO - Executing <Task(PythonOperator): clean_data> on 2024-07-18 00:00:00+00:00
[2024-07-19T11:45:44.725+0000] {warnings.py:112} WARNING - /home/***/.local/lib/python3.12/site-packages/***/task/task_runner/standard_task_runner.py:62: DeprecationWarning: This process (pid=878) is multi-threaded, use of fork() may lead to deadlocks in the child.
  pid = os.fork()

[2024-07-19T11:45:44.731+0000] {standard_task_runner.py:64} INFO - Started process 903 to run task
[2024-07-19T11:45:44.733+0000] {standard_task_runner.py:90} INFO - Running: ['***', 'tasks', 'run', 'data_cleaning', 'clean_data', 'scheduled__2024-07-18T00:00:00+00:00', '--job-id', '47', '--raw', '--subdir', 'DAGS_FOLDER/data_cleaning_dag.py', '--cfg-path', '/tmp/tmpqg4bkf9q']
[2024-07-19T11:45:44.749+0000] {standard_task_runner.py:91} INFO - Job 47: Subtask clean_data
[2024-07-19T11:45:44.885+0000] {task_command.py:426} INFO - Running <TaskInstance: data_cleaning.clean_data scheduled__2024-07-18T00:00:00+00:00 [running]> on host 6e10856c4017
[2024-07-19T11:45:44.992+0000] {taskinstance.py:2648} INFO - Exporting env vars: AIRFLOW_CTX_DAG_OWNER='***' AIRFLOW_CTX_DAG_ID='data_cleaning' AIRFLOW_CTX_TASK_ID='clean_data' AIRFLOW_CTX_EXECUTION_DATE='2024-07-18T00:00:00+00:00' AIRFLOW_CTX_TRY_NUMBER='1' AIRFLOW_CTX_DAG_RUN_ID='scheduled__2024-07-18T00:00:00+00:00'
[2024-07-19T11:45:44.994+0000] {taskinstance.py:430} INFO - ::endgroup::
[2024-07-19T11:45:45.011+0000] {taskinstance.py:441} INFO - ::group::Post task execution logs
[2024-07-19T11:45:45.012+0000] {taskinstance.py:2905} ERROR - Task failed with exception
Traceback (most recent call last):
  File "/home/airflow/.local/lib/python3.12/site-packages/airflow/models/taskinstance.py", line 465, in _execute_task
    result = _execute_callable(context=context, **execute_callable_kwargs)
             ^^^^^^^^^^^^^^^^^^^^^^^^^^^^^^^^^^^^^^^^^^^^^^^^^^^^^^^^^^^^^
  File "/home/airflow/.local/lib/python3.12/site-packages/airflow/models/taskinstance.py", line 432, in _execute_callable
    return execute_callable(context=context, **execute_callable_kwargs)
           ^^^^^^^^^^^^^^^^^^^^^^^^^^^^^^^^^^^^^^^^^^^^^^^^^^^^^^^^^^^^
  File "/home/airflow/.local/lib/python3.12/site-packages/airflow/models/baseoperator.py", line 401, in wrapper
    return func(self, *args, **kwargs)
           ^^^^^^^^^^^^^^^^^^^^^^^^^^^
  File "/home/airflow/.local/lib/python3.12/site-packages/airflow/operators/python.py", line 235, in execute
    return_value = self.execute_callable()
                   ^^^^^^^^^^^^^^^^^^^^^^^
  File "/home/airflow/.local/lib/python3.12/site-packages/airflow/operators/python.py", line 252, in execute_callable
    return self.python_callable(*self.op_args, **self.op_kwargs)
           ^^^^^^^^^^^^^^^^^^^^^^^^^^^^^^^^^^^^^^^^^^^^^^^^^^^^^
  File "/opt/airflow/dags/data_cleaning_dag.py", line 111, in main
    data = pd.read_csv(data_path, delimiter=';', decimal=',')
           ^^^^^^^^^^^^^^^^^^^^^^^^^^^^^^^^^^^^^^^^^^^^^^^^^^
  File "/home/airflow/.local/lib/python3.12/site-packages/pandas/io/parsers/readers.py", line 948, in read_csv
    return _read(filepath_or_buffer, kwds)
           ^^^^^^^^^^^^^^^^^^^^^^^^^^^^^^^
  File "/home/airflow/.local/lib/python3.12/site-packages/pandas/io/parsers/readers.py", line 611, in _read
    parser = TextFileReader(filepath_or_buffer, **kwds)
             ^^^^^^^^^^^^^^^^^^^^^^^^^^^^^^^^^^^^^^^^^^
  File "/home/airflow/.local/lib/python3.12/site-packages/pandas/io/parsers/readers.py", line 1448, in __init__
    self._engine = self._make_engine(f, self.engine)
                   ^^^^^^^^^^^^^^^^^^^^^^^^^^^^^^^^^
  File "/home/airflow/.local/lib/python3.12/site-packages/pandas/io/parsers/readers.py", line 1705, in _make_engine
    self.handles = get_handle(
                   ^^^^^^^^^^^
  File "/home/airflow/.local/lib/python3.12/site-packages/pandas/io/common.py", line 863, in get_handle
    handle = open(
             ^^^^^
FileNotFoundError: [Errno 2] No such file or directory: '../data/dataset.csv'
[2024-07-19T11:45:45.025+0000] {taskinstance.py:1206} INFO - Marking task as UP_FOR_RETRY. dag_id=data_cleaning, task_id=clean_data, run_id=scheduled__2024-07-18T00:00:00+00:00, execution_date=20240718T000000, start_date=20240719T114544, end_date=20240719T114545
[2024-07-19T11:45:45.041+0000] {standard_task_runner.py:110} ERROR - Failed to execute job 47 for task clean_data ([Errno 2] No such file or directory: '../data/dataset.csv'; 903)
[2024-07-19T11:45:45.104+0000] {local_task_job_runner.py:243} INFO - Task exited with return code 1
[2024-07-19T11:45:45.198+0000] {taskinstance.py:3503} INFO - 0 downstream tasks scheduled from follow-on schedule check
[2024-07-19T11:45:45.203+0000] {local_task_job_runner.py:222} INFO - ::endgroup::
