[2024-07-19T10:52:34.311+0000] {local_task_job_runner.py:120} INFO - ::group::Pre task execution logs
[2024-07-19T10:52:34.325+0000] {taskinstance.py:2076} INFO - Dependencies all met for dep_context=non-requeueable deps ti=<TaskInstance: data_cleaning_dag.clean_data scheduled__2024-07-18T00:00:00+00:00 [queued]>
[2024-07-19T10:52:34.329+0000] {taskinstance.py:2076} INFO - Dependencies all met for dep_context=requeueable deps ti=<TaskInstance: data_cleaning_dag.clean_data scheduled__2024-07-18T00:00:00+00:00 [queued]>
[2024-07-19T10:52:34.330+0000] {taskinstance.py:2306} INFO - Starting attempt 1 of 2
[2024-07-19T10:52:34.341+0000] {taskinstance.py:2330} INFO - Executing <Task(PythonOperator): clean_data> on 2024-07-18 00:00:00+00:00
[2024-07-19T10:52:34.350+0000] {warnings.py:112} WARNING - /home/***/.local/lib/python3.12/site-packages/***/task/task_runner/standard_task_runner.py:62: DeprecationWarning: This process (pid=78) is multi-threaded, use of fork() may lead to deadlocks in the child.
  pid = os.fork()

[2024-07-19T10:52:34.352+0000] {standard_task_runner.py:64} INFO - Started process 96 to run task
[2024-07-19T10:52:34.352+0000] {standard_task_runner.py:90} INFO - Running: ['***', 'tasks', 'run', 'data_cleaning_dag', 'clean_data', 'scheduled__2024-07-18T00:00:00+00:00', '--job-id', '28', '--raw', '--subdir', 'DAGS_FOLDER/data_cleaning_dag.py', '--cfg-path', '/tmp/tmpc6ca2hmq']
[2024-07-19T10:52:34.377+0000] {standard_task_runner.py:91} INFO - Job 28: Subtask clean_data
[2024-07-19T10:52:34.422+0000] {task_command.py:426} INFO - Running <TaskInstance: data_cleaning_dag.clean_data scheduled__2024-07-18T00:00:00+00:00 [running]> on host 734c313f014e
[2024-07-19T10:52:34.511+0000] {taskinstance.py:2648} INFO - Exporting env vars: AIRFLOW_CTX_DAG_OWNER='***' AIRFLOW_CTX_DAG_ID='data_cleaning_dag' AIRFLOW_CTX_TASK_ID='clean_data' AIRFLOW_CTX_EXECUTION_DATE='2024-07-18T00:00:00+00:00' AIRFLOW_CTX_TRY_NUMBER='1' AIRFLOW_CTX_DAG_RUN_ID='scheduled__2024-07-18T00:00:00+00:00'
[2024-07-19T10:52:34.513+0000] {taskinstance.py:430} INFO - ::endgroup::
[2024-07-19T10:52:34.542+0000] {taskinstance.py:441} INFO - ::group::Post task execution logs
[2024-07-19T10:52:34.545+0000] {taskinstance.py:2905} ERROR - Task failed with exception
Traceback (most recent call last):
  File "/home/airflow/.local/lib/python3.12/site-packages/airflow/models/taskinstance.py", line 465, in _execute_task
    result = _execute_callable(context=context, **execute_callable_kwargs)
             ^^^^^^^^^^^^^^^^^^^^^^^^^^^^^^^^^^^^^^^^^^^^^^^^^^^^^^^^^^^^^
  File "/home/airflow/.local/lib/python3.12/site-packages/airflow/models/taskinstance.py", line 432, in _execute_callable
    return execute_callable(context=context, **execute_callable_kwargs)
           ^^^^^^^^^^^^^^^^^^^^^^^^^^^^^^^^^^^^^^^^^^^^^^^^^^^^^^^^^^^^
  File "/home/airflow/.local/lib/python3.12/site-packages/airflow/models/baseoperator.py", line 401, in wrapper
    return func(self, *args, **kwargs)
           ^^^^^^^^^^^^^^^^^^^^^^^^^^^
  File "/home/airflow/.local/lib/python3.12/site-packages/airflow/operators/python.py", line 235, in execute
    return_value = self.execute_callable()
                   ^^^^^^^^^^^^^^^^^^^^^^^
  File "/home/airflow/.local/lib/python3.12/site-packages/airflow/operators/python.py", line 252, in execute_callable
    return self.python_callable(*self.op_args, **self.op_kwargs)
           ^^^^^^^^^^^^^^^^^^^^^^^^^^^^^^^^^^^^^^^^^^^^^^^^^^^^^
  File "/opt/airflow/dags/data_cleaning_OOP.py", line 105, in main
    data = pd.read_csv('../../data/dataset.csv', delimiter=';', decimal=',')
           ^^^^^^^^^^^^^^^^^^^^^^^^^^^^^^^^^^^^^^^^^^^^^^^^^^^^^^^^^^^^^^^^^
  File "/home/airflow/.local/lib/python3.12/site-packages/pandas/io/parsers/readers.py", line 948, in read_csv
    return _read(filepath_or_buffer, kwds)
           ^^^^^^^^^^^^^^^^^^^^^^^^^^^^^^^
  File "/home/airflow/.local/lib/python3.12/site-packages/pandas/io/parsers/readers.py", line 611, in _read
    parser = TextFileReader(filepath_or_buffer, **kwds)
             ^^^^^^^^^^^^^^^^^^^^^^^^^^^^^^^^^^^^^^^^^^
  File "/home/airflow/.local/lib/python3.12/site-packages/pandas/io/parsers/readers.py", line 1448, in __init__
    self._engine = self._make_engine(f, self.engine)
                   ^^^^^^^^^^^^^^^^^^^^^^^^^^^^^^^^^
  File "/home/airflow/.local/lib/python3.12/site-packages/pandas/io/parsers/readers.py", line 1705, in _make_engine
    self.handles = get_handle(
                   ^^^^^^^^^^^
  File "/home/airflow/.local/lib/python3.12/site-packages/pandas/io/common.py", line 863, in get_handle
    handle = open(
             ^^^^^
FileNotFoundError: [Errno 2] No such file or directory: '../../data/dataset.csv'
[2024-07-19T10:52:34.552+0000] {taskinstance.py:1206} INFO - Marking task as UP_FOR_RETRY. dag_id=data_cleaning_dag, task_id=clean_data, run_id=scheduled__2024-07-18T00:00:00+00:00, execution_date=20240718T000000, start_date=20240719T105234, end_date=20240719T105234
[2024-07-19T10:52:34.559+0000] {standard_task_runner.py:110} ERROR - Failed to execute job 28 for task clean_data ([Errno 2] No such file or directory: '../../data/dataset.csv'; 96)
[2024-07-19T10:52:34.598+0000] {local_task_job_runner.py:243} INFO - Task exited with return code 1
[2024-07-19T10:52:34.618+0000] {taskinstance.py:3503} INFO - 0 downstream tasks scheduled from follow-on schedule check
[2024-07-19T10:52:34.619+0000] {local_task_job_runner.py:222} INFO - ::endgroup::
[2024-07-19T10:55:47.983+0000] {local_task_job_runner.py:120} INFO - ::group::Pre task execution logs
[2024-07-19T10:55:47.997+0000] {taskinstance.py:2076} INFO - Dependencies all met for dep_context=non-requeueable deps ti=<TaskInstance: data_cleaning_dag.clean_data scheduled__2024-07-18T00:00:00+00:00 [queued]>
[2024-07-19T10:55:48.002+0000] {taskinstance.py:2076} INFO - Dependencies all met for dep_context=requeueable deps ti=<TaskInstance: data_cleaning_dag.clean_data scheduled__2024-07-18T00:00:00+00:00 [queued]>
[2024-07-19T10:55:48.002+0000] {taskinstance.py:2306} INFO - Starting attempt 1 of 2
[2024-07-19T10:55:48.008+0000] {taskinstance.py:2330} INFO - Executing <Task(PythonOperator): clean_data> on 2024-07-18 00:00:00+00:00
[2024-07-19T10:55:48.015+0000] {warnings.py:112} WARNING - /home/***/.local/lib/python3.12/site-packages/***/task/task_runner/standard_task_runner.py:62: DeprecationWarning: This process (pid=149) is multi-threaded, use of fork() may lead to deadlocks in the child.
  pid = os.fork()

[2024-07-19T10:55:48.017+0000] {standard_task_runner.py:64} INFO - Started process 158 to run task
[2024-07-19T10:55:48.017+0000] {standard_task_runner.py:90} INFO - Running: ['***', 'tasks', 'run', 'data_cleaning_dag', 'clean_data', 'scheduled__2024-07-18T00:00:00+00:00', '--job-id', '31', '--raw', '--subdir', 'DAGS_FOLDER/data_cleaning_dag.py', '--cfg-path', '/tmp/tmp7ukz48uv']
[2024-07-19T10:55:48.019+0000] {standard_task_runner.py:91} INFO - Job 31: Subtask clean_data
[2024-07-19T10:55:48.066+0000] {task_command.py:426} INFO - Running <TaskInstance: data_cleaning_dag.clean_data scheduled__2024-07-18T00:00:00+00:00 [running]> on host 734c313f014e
[2024-07-19T10:55:48.118+0000] {taskinstance.py:2648} INFO - Exporting env vars: AIRFLOW_CTX_DAG_OWNER='***' AIRFLOW_CTX_DAG_ID='data_cleaning_dag' AIRFLOW_CTX_TASK_ID='clean_data' AIRFLOW_CTX_EXECUTION_DATE='2024-07-18T00:00:00+00:00' AIRFLOW_CTX_TRY_NUMBER='1' AIRFLOW_CTX_DAG_RUN_ID='scheduled__2024-07-18T00:00:00+00:00'
[2024-07-19T10:55:48.118+0000] {taskinstance.py:430} INFO - ::endgroup::
[2024-07-19T10:55:48.127+0000] {taskinstance.py:441} INFO - ::group::Post task execution logs
[2024-07-19T10:55:48.128+0000] {taskinstance.py:2905} ERROR - Task failed with exception
Traceback (most recent call last):
  File "/home/airflow/.local/lib/python3.12/site-packages/airflow/models/taskinstance.py", line 465, in _execute_task
    result = _execute_callable(context=context, **execute_callable_kwargs)
             ^^^^^^^^^^^^^^^^^^^^^^^^^^^^^^^^^^^^^^^^^^^^^^^^^^^^^^^^^^^^^
  File "/home/airflow/.local/lib/python3.12/site-packages/airflow/models/taskinstance.py", line 432, in _execute_callable
    return execute_callable(context=context, **execute_callable_kwargs)
           ^^^^^^^^^^^^^^^^^^^^^^^^^^^^^^^^^^^^^^^^^^^^^^^^^^^^^^^^^^^^
  File "/home/airflow/.local/lib/python3.12/site-packages/airflow/models/baseoperator.py", line 401, in wrapper
    return func(self, *args, **kwargs)
           ^^^^^^^^^^^^^^^^^^^^^^^^^^^
  File "/home/airflow/.local/lib/python3.12/site-packages/airflow/operators/python.py", line 235, in execute
    return_value = self.execute_callable()
                   ^^^^^^^^^^^^^^^^^^^^^^^
  File "/home/airflow/.local/lib/python3.12/site-packages/airflow/operators/python.py", line 252, in execute_callable
    return self.python_callable(*self.op_args, **self.op_kwargs)
           ^^^^^^^^^^^^^^^^^^^^^^^^^^^^^^^^^^^^^^^^^^^^^^^^^^^^^
  File "/opt/airflow/dags/data_cleaning_OOP.py", line 105, in main
    data = pd.read_csv('../../data/dataset.csv', delimiter=';', decimal=',')
           ^^^^^^^^^^^^^^^^^^^^^^^^^^^^^^^^^^^^^^^^^^^^^^^^^^^^^^^^^^^^^^^^^
  File "/home/airflow/.local/lib/python3.12/site-packages/pandas/io/parsers/readers.py", line 948, in read_csv
    return _read(filepath_or_buffer, kwds)
           ^^^^^^^^^^^^^^^^^^^^^^^^^^^^^^^
  File "/home/airflow/.local/lib/python3.12/site-packages/pandas/io/parsers/readers.py", line 611, in _read
    parser = TextFileReader(filepath_or_buffer, **kwds)
             ^^^^^^^^^^^^^^^^^^^^^^^^^^^^^^^^^^^^^^^^^^
  File "/home/airflow/.local/lib/python3.12/site-packages/pandas/io/parsers/readers.py", line 1448, in __init__
    self._engine = self._make_engine(f, self.engine)
                   ^^^^^^^^^^^^^^^^^^^^^^^^^^^^^^^^^
  File "/home/airflow/.local/lib/python3.12/site-packages/pandas/io/parsers/readers.py", line 1705, in _make_engine
    self.handles = get_handle(
                   ^^^^^^^^^^^
  File "/home/airflow/.local/lib/python3.12/site-packages/pandas/io/common.py", line 863, in get_handle
    handle = open(
             ^^^^^
FileNotFoundError: [Errno 2] No such file or directory: '../../data/dataset.csv'
[2024-07-19T10:55:48.138+0000] {taskinstance.py:1206} INFO - Marking task as UP_FOR_RETRY. dag_id=data_cleaning_dag, task_id=clean_data, run_id=scheduled__2024-07-18T00:00:00+00:00, execution_date=20240718T000000, start_date=20240719T105547, end_date=20240719T105548
[2024-07-19T10:55:48.149+0000] {standard_task_runner.py:110} ERROR - Failed to execute job 31 for task clean_data ([Errno 2] No such file or directory: '../../data/dataset.csv'; 158)
[2024-07-19T10:55:48.161+0000] {local_task_job_runner.py:243} INFO - Task exited with return code 1
[2024-07-19T10:55:48.173+0000] {taskinstance.py:3503} INFO - 0 downstream tasks scheduled from follow-on schedule check
[2024-07-19T10:55:48.174+0000] {local_task_job_runner.py:222} INFO - ::endgroup::
