[2024-07-21T07:52:04.448+0000] {local_task_job_runner.py:120} INFO - ::group::Pre task execution logs
[2024-07-21T07:52:04.462+0000] {taskinstance.py:2076} INFO - Dependencies all met for dep_context=non-requeueable deps ti=<TaskInstance: example_dag.print_hello manual__2024-07-21T07:47:02.340970+00:00 [queued]>
[2024-07-21T07:52:04.465+0000] {taskinstance.py:2076} INFO - Dependencies all met for dep_context=requeueable deps ti=<TaskInstance: example_dag.print_hello manual__2024-07-21T07:47:02.340970+00:00 [queued]>
[2024-07-21T07:52:04.466+0000] {taskinstance.py:2306} INFO - Starting attempt 2 of 2
[2024-07-21T07:52:04.472+0000] {taskinstance.py:2330} INFO - Executing <Task(PythonOperator): print_hello> on 2024-07-21 07:47:02.340970+00:00
[2024-07-21T07:52:04.476+0000] {warnings.py:112} WARNING - /home/***/.local/lib/python3.12/site-packages/***/task/task_runner/standard_task_runner.py:62: DeprecationWarning: This process (pid=345) is multi-threaded, use of fork() may lead to deadlocks in the child.
  pid = os.fork()

[2024-07-21T07:52:04.477+0000] {standard_task_runner.py:64} INFO - Started process 346 to run task
[2024-07-21T07:52:04.477+0000] {standard_task_runner.py:90} INFO - Running: ['***', 'tasks', 'run', 'example_dag', 'print_hello', 'manual__2024-07-21T07:47:02.340970+00:00', '--job-id', '441', '--raw', '--subdir', 'DAGS_FOLDER/hello_dag.py', '--cfg-path', '/tmp/tmp2c7_i320']
[2024-07-21T07:52:04.478+0000] {standard_task_runner.py:91} INFO - Job 441: Subtask print_hello
[2024-07-21T07:52:04.501+0000] {task_command.py:426} INFO - Running <TaskInstance: example_dag.print_hello manual__2024-07-21T07:47:02.340970+00:00 [running]> on host 6e10856c4017
[2024-07-21T07:52:04.539+0000] {taskinstance.py:2648} INFO - Exporting env vars: AIRFLOW_CTX_DAG_OWNER='***' AIRFLOW_CTX_DAG_ID='example_dag' AIRFLOW_CTX_TASK_ID='print_hello' AIRFLOW_CTX_EXECUTION_DATE='2024-07-21T07:47:02.340970+00:00' AIRFLOW_CTX_TRY_NUMBER='2' AIRFLOW_CTX_DAG_RUN_ID='manual__2024-07-21T07:47:02.340970+00:00'
[2024-07-21T07:52:04.540+0000] {taskinstance.py:430} INFO - ::endgroup::
[2024-07-21T07:52:04.547+0000] {logging_mixin.py:188} INFO - Hello, World!
[2024-07-21T07:52:04.547+0000] {taskinstance.py:441} INFO - ::group::Post task execution logs
[2024-07-21T07:52:04.547+0000] {taskinstance.py:2905} ERROR - Task failed with exception
Traceback (most recent call last):
  File "/home/airflow/.local/lib/python3.12/site-packages/airflow/models/taskinstance.py", line 465, in _execute_task
    result = _execute_callable(context=context, **execute_callable_kwargs)
             ^^^^^^^^^^^^^^^^^^^^^^^^^^^^^^^^^^^^^^^^^^^^^^^^^^^^^^^^^^^^^
  File "/home/airflow/.local/lib/python3.12/site-packages/airflow/models/taskinstance.py", line 432, in _execute_callable
    return execute_callable(context=context, **execute_callable_kwargs)
           ^^^^^^^^^^^^^^^^^^^^^^^^^^^^^^^^^^^^^^^^^^^^^^^^^^^^^^^^^^^^
  File "/home/airflow/.local/lib/python3.12/site-packages/airflow/models/baseoperator.py", line 401, in wrapper
    return func(self, *args, **kwargs)
           ^^^^^^^^^^^^^^^^^^^^^^^^^^^
  File "/home/airflow/.local/lib/python3.12/site-packages/airflow/operators/python.py", line 235, in execute
    return_value = self.execute_callable()
                   ^^^^^^^^^^^^^^^^^^^^^^^
  File "/home/airflow/.local/lib/python3.12/site-packages/airflow/operators/python.py", line 252, in execute_callable
    return self.python_callable(*self.op_args, **self.op_kwargs)
           ^^^^^^^^^^^^^^^^^^^^^^^^^^^^^^^^^^^^^^^^^^^^^^^^^^^^^
  File "/opt/airflow/dags/hello_dag.py", line 7, in print_hello
    with open('../data/output.txt', 'w') as f:
         ^^^^^^^^^^^^^^^^^^^^^^^^^^^^^^^
FileNotFoundError: [Errno 2] No such file or directory: '../data/output.txt'
[2024-07-21T07:52:04.552+0000] {taskinstance.py:1206} INFO - Marking task as FAILED. dag_id=example_dag, task_id=print_hello, run_id=manual__2024-07-21T07:47:02.340970+00:00, execution_date=20240721T074702, start_date=20240721T075204, end_date=20240721T075204
[2024-07-21T07:52:04.558+0000] {standard_task_runner.py:110} ERROR - Failed to execute job 441 for task print_hello ([Errno 2] No such file or directory: '../data/output.txt'; 346)
[2024-07-21T07:52:04.580+0000] {local_task_job_runner.py:243} INFO - Task exited with return code 1
[2024-07-21T07:52:04.589+0000] {taskinstance.py:3503} INFO - 0 downstream tasks scheduled from follow-on schedule check
[2024-07-21T07:52:04.590+0000] {local_task_job_runner.py:222} INFO - ::endgroup::
