[2024-07-21T08:53:08.233+0000] {local_task_job_runner.py:120} INFO - ::group::Pre task execution logs
[2024-07-21T08:53:08.280+0000] {taskinstance.py:2076} INFO - Dependencies all met for dep_context=non-requeueable deps ti=<TaskInstance: churn_model_DAG.model_training scheduled__2024-07-20T00:00:00+00:00 [queued]>
[2024-07-21T08:53:08.586+0000] {taskinstance.py:2076} INFO - Dependencies all met for dep_context=requeueable deps ti=<TaskInstance: churn_model_DAG.model_training scheduled__2024-07-20T00:00:00+00:00 [queued]>
[2024-07-21T08:53:08.588+0000] {taskinstance.py:2306} INFO - Starting attempt 1 of 2
[2024-07-21T08:53:08.612+0000] {taskinstance.py:2330} INFO - Executing <Task(PythonOperator): model_training> on 2024-07-20 00:00:00+00:00
[2024-07-21T08:53:08.669+0000] {warnings.py:112} WARNING - /home/***/.local/lib/python3.12/site-packages/***/task/task_runner/standard_task_runner.py:62: DeprecationWarning: This process (pid=292) is multi-threaded, use of fork() may lead to deadlocks in the child.
  pid = os.fork()

[2024-07-21T08:53:08.671+0000] {standard_task_runner.py:64} INFO - Started process 318 to run task
[2024-07-21T08:53:08.670+0000] {standard_task_runner.py:90} INFO - Running: ['***', 'tasks', 'run', 'churn_model_DAG', 'model_training', 'scheduled__2024-07-20T00:00:00+00:00', '--job-id', '460', '--raw', '--subdir', 'DAGS_FOLDER/model_pipeline_DAG.py', '--cfg-path', '/tmp/tmphvs9yd6g']
[2024-07-21T08:53:08.674+0000] {standard_task_runner.py:91} INFO - Job 460: Subtask model_training
[2024-07-21T08:53:08.707+0000] {task_command.py:426} INFO - Running <TaskInstance: churn_model_DAG.model_training scheduled__2024-07-20T00:00:00+00:00 [running]> on host 6e10856c4017
[2024-07-21T08:53:08.751+0000] {taskinstance.py:2648} INFO - Exporting env vars: AIRFLOW_CTX_DAG_OWNER='***' AIRFLOW_CTX_DAG_ID='churn_model_DAG' AIRFLOW_CTX_TASK_ID='model_training' AIRFLOW_CTX_EXECUTION_DATE='2024-07-20T00:00:00+00:00' AIRFLOW_CTX_TRY_NUMBER='1' AIRFLOW_CTX_DAG_RUN_ID='scheduled__2024-07-20T00:00:00+00:00'
[2024-07-21T08:53:08.752+0000] {taskinstance.py:430} INFO - ::endgroup::
[2024-07-21T08:53:08.993+0000] {taskinstance.py:441} INFO - ::group::Post task execution logs
[2024-07-21T08:53:08.994+0000] {taskinstance.py:2905} ERROR - Task failed with exception
Traceback (most recent call last):
  File "/home/airflow/.local/lib/python3.12/site-packages/airflow/models/taskinstance.py", line 465, in _execute_task
    result = _execute_callable(context=context, **execute_callable_kwargs)
             ^^^^^^^^^^^^^^^^^^^^^^^^^^^^^^^^^^^^^^^^^^^^^^^^^^^^^^^^^^^^^
  File "/home/airflow/.local/lib/python3.12/site-packages/airflow/models/taskinstance.py", line 432, in _execute_callable
    return execute_callable(context=context, **execute_callable_kwargs)
           ^^^^^^^^^^^^^^^^^^^^^^^^^^^^^^^^^^^^^^^^^^^^^^^^^^^^^^^^^^^^
  File "/home/airflow/.local/lib/python3.12/site-packages/airflow/models/baseoperator.py", line 401, in wrapper
    return func(self, *args, **kwargs)
           ^^^^^^^^^^^^^^^^^^^^^^^^^^^
  File "/home/airflow/.local/lib/python3.12/site-packages/airflow/operators/python.py", line 235, in execute
    return_value = self.execute_callable()
                   ^^^^^^^^^^^^^^^^^^^^^^^
  File "/home/airflow/.local/lib/python3.12/site-packages/airflow/operators/python.py", line 252, in execute_callable
    return self.python_callable(*self.op_args, **self.op_kwargs)
           ^^^^^^^^^^^^^^^^^^^^^^^^^^^^^^^^^^^^^^^^^^^^^^^^^^^^^
  File "/opt/airflow/dags/model_pipeline_DAG.py", line 34, in run_model_training
    trainer.train_and_evaluate()
  File "/opt/airflow/dags/model_train.py", line 62, in train_and_evaluate
    X_train, X_test, y_train, y_test = self.load_data()
                                       ^^^^^^^^^^^^^^^^
  File "/opt/airflow/dags/model_train.py", line 29, in load_data
    X = data.drop(['churn'], axis=1)
        ^^^^^^^^^^^^^^^^^^^^^^^^^^^^
  File "/home/airflow/.local/lib/python3.12/site-packages/pandas/core/frame.py", line 5344, in drop
    return super().drop(
           ^^^^^^^^^^^^^
  File "/home/airflow/.local/lib/python3.12/site-packages/pandas/core/generic.py", line 4711, in drop
    obj = obj._drop_axis(labels, axis, level=level, errors=errors)
          ^^^^^^^^^^^^^^^^^^^^^^^^^^^^^^^^^^^^^^^^^^^^^^^^^^^^^^^^
  File "/home/airflow/.local/lib/python3.12/site-packages/pandas/core/generic.py", line 4753, in _drop_axis
    new_axis = axis.drop(labels, errors=errors)
               ^^^^^^^^^^^^^^^^^^^^^^^^^^^^^^^^
  File "/home/airflow/.local/lib/python3.12/site-packages/pandas/core/indexes/base.py", line 7000, in drop
    raise KeyError(f"{labels[mask].tolist()} not found in axis")
KeyError: "['churn'] not found in axis"
[2024-07-21T08:53:09.008+0000] {taskinstance.py:1206} INFO - Marking task as UP_FOR_RETRY. dag_id=churn_model_DAG, task_id=model_training, run_id=scheduled__2024-07-20T00:00:00+00:00, execution_date=20240720T000000, start_date=20240721T085308, end_date=20240721T085309
[2024-07-21T08:53:09.017+0000] {standard_task_runner.py:110} ERROR - Failed to execute job 460 for task model_training ("['churn'] not found in axis"; 318)
[2024-07-21T08:53:09.023+0000] {local_task_job_runner.py:243} INFO - Task exited with return code 1
[2024-07-21T08:53:09.033+0000] {taskinstance.py:3503} INFO - 0 downstream tasks scheduled from follow-on schedule check
[2024-07-21T08:53:09.034+0000] {local_task_job_runner.py:222} INFO - ::endgroup::
[2024-07-21T08:59:59.317+0000] {local_task_job_runner.py:120} INFO - ::group::Pre task execution logs
[2024-07-21T08:59:59.494+0000] {taskinstance.py:2076} INFO - Dependencies all met for dep_context=non-requeueable deps ti=<TaskInstance: churn_model_DAG.model_training scheduled__2024-07-20T00:00:00+00:00 [queued]>
[2024-07-21T08:59:59.499+0000] {taskinstance.py:2076} INFO - Dependencies all met for dep_context=requeueable deps ti=<TaskInstance: churn_model_DAG.model_training scheduled__2024-07-20T00:00:00+00:00 [queued]>
[2024-07-21T08:59:59.503+0000] {taskinstance.py:2306} INFO - Starting attempt 1 of 2
[2024-07-21T08:59:59.509+0000] {taskinstance.py:2330} INFO - Executing <Task(PythonOperator): model_training> on 2024-07-20 00:00:00+00:00
[2024-07-21T08:59:59.517+0000] {warnings.py:112} WARNING - /home/***/.local/lib/python3.12/site-packages/***/task/task_runner/standard_task_runner.py:62: DeprecationWarning: This process (pid=528) is multi-threaded, use of fork() may lead to deadlocks in the child.
  pid = os.fork()

[2024-07-21T08:59:59.518+0000] {standard_task_runner.py:64} INFO - Started process 545 to run task
[2024-07-21T08:59:59.518+0000] {standard_task_runner.py:90} INFO - Running: ['***', 'tasks', 'run', 'churn_model_DAG', 'model_training', 'scheduled__2024-07-20T00:00:00+00:00', '--job-id', '466', '--raw', '--subdir', 'DAGS_FOLDER/model_pipeline_DAG.py', '--cfg-path', '/tmp/tmprdheqxyo']
[2024-07-21T08:59:59.522+0000] {standard_task_runner.py:91} INFO - Job 466: Subtask model_training
[2024-07-21T08:59:59.552+0000] {task_command.py:426} INFO - Running <TaskInstance: churn_model_DAG.model_training scheduled__2024-07-20T00:00:00+00:00 [running]> on host 6e10856c4017
[2024-07-21T08:59:59.604+0000] {taskinstance.py:2648} INFO - Exporting env vars: AIRFLOW_CTX_DAG_OWNER='***' AIRFLOW_CTX_DAG_ID='churn_model_DAG' AIRFLOW_CTX_TASK_ID='model_training' AIRFLOW_CTX_EXECUTION_DATE='2024-07-20T00:00:00+00:00' AIRFLOW_CTX_TRY_NUMBER='1' AIRFLOW_CTX_DAG_RUN_ID='scheduled__2024-07-20T00:00:00+00:00'
[2024-07-21T08:59:59.608+0000] {taskinstance.py:430} INFO - ::endgroup::
[2024-07-21T08:59:59.972+0000] {taskinstance.py:441} INFO - ::group::Post task execution logs
[2024-07-21T08:59:59.973+0000] {taskinstance.py:2905} ERROR - Task failed with exception
Traceback (most recent call last):
  File "/home/airflow/.local/lib/python3.12/site-packages/airflow/models/taskinstance.py", line 465, in _execute_task
    result = _execute_callable(context=context, **execute_callable_kwargs)
             ^^^^^^^^^^^^^^^^^^^^^^^^^^^^^^^^^^^^^^^^^^^^^^^^^^^^^^^^^^^^^
  File "/home/airflow/.local/lib/python3.12/site-packages/airflow/models/taskinstance.py", line 432, in _execute_callable
    return execute_callable(context=context, **execute_callable_kwargs)
           ^^^^^^^^^^^^^^^^^^^^^^^^^^^^^^^^^^^^^^^^^^^^^^^^^^^^^^^^^^^^
  File "/home/airflow/.local/lib/python3.12/site-packages/airflow/models/baseoperator.py", line 401, in wrapper
    return func(self, *args, **kwargs)
           ^^^^^^^^^^^^^^^^^^^^^^^^^^^
  File "/home/airflow/.local/lib/python3.12/site-packages/airflow/operators/python.py", line 235, in execute
    return_value = self.execute_callable()
                   ^^^^^^^^^^^^^^^^^^^^^^^
  File "/home/airflow/.local/lib/python3.12/site-packages/airflow/operators/python.py", line 252, in execute_callable
    return self.python_callable(*self.op_args, **self.op_kwargs)
           ^^^^^^^^^^^^^^^^^^^^^^^^^^^^^^^^^^^^^^^^^^^^^^^^^^^^^
  File "/opt/airflow/dags/model_pipeline_DAG.py", line 34, in run_model_training
    trainer.train_and_evaluate()
  File "/opt/airflow/dags/model_train.py", line 68, in train_and_evaluate
    with mlflow.start_run():
         ^^^^^^^^^^^^^^^^^^
  File "/home/airflow/.local/lib/python3.12/site-packages/mlflow/tracking/fluent.py", line 313, in start_run
    client = MlflowClient()
             ^^^^^^^^^^^^^^
  File "/home/airflow/.local/lib/python3.12/site-packages/mlflow/tracking/client.py", line 134, in __init__
    self._tracking_client = TrackingServiceClient(final_tracking_uri)
                            ^^^^^^^^^^^^^^^^^^^^^^^^^^^^^^^^^^^^^^^^^
  File "/home/airflow/.local/lib/python3.12/site-packages/mlflow/tracking/_tracking_service/client.py", line 79, in __init__
    self.store
  File "/home/airflow/.local/lib/python3.12/site-packages/mlflow/tracking/_tracking_service/client.py", line 83, in store
    return utils._get_store(self.tracking_uri)
           ^^^^^^^^^^^^^^^^^^^^^^^^^^^^^^^^^^^
  File "/home/airflow/.local/lib/python3.12/site-packages/mlflow/tracking/_tracking_service/utils.py", line 205, in _get_store
    return _tracking_store_registry.get_store(store_uri, artifact_uri)
           ^^^^^^^^^^^^^^^^^^^^^^^^^^^^^^^^^^^^^^^^^^^^^^^^^^^^^^^^^^^
  File "/home/airflow/.local/lib/python3.12/site-packages/mlflow/tracking/_tracking_service/registry.py", line 42, in get_store
    return self._get_store_with_resolved_uri(resolved_store_uri, artifact_uri)
           ^^^^^^^^^^^^^^^^^^^^^^^^^^^^^^^^^^^^^^^^^^^^^^^^^^^^^^^^^^^^^^^^^^^
  File "/home/airflow/.local/lib/python3.12/site-packages/mlflow/tracking/_tracking_service/registry.py", line 52, in _get_store_with_resolved_uri
    return builder(store_uri=resolved_store_uri, artifact_uri=artifact_uri)
           ^^^^^^^^^^^^^^^^^^^^^^^^^^^^^^^^^^^^^^^^^^^^^^^^^^^^^^^^^^^^^^^^
  File "/home/airflow/.local/lib/python3.12/site-packages/mlflow/tracking/_tracking_service/utils.py", line 130, in _get_file_store
    return FileStore(store_uri, store_uri)
           ^^^^^^^^^^^^^^^^^^^^^^^^^^^^^^^
  File "/home/airflow/.local/lib/python3.12/site-packages/mlflow/store/tracking/file_store.py", line 187, in __init__
    self._create_default_experiment()
  File "/home/airflow/.local/lib/python3.12/site-packages/mlflow/store/tracking/file_store.py", line 193, in _create_default_experiment
    mkdir(self.root_directory)
  File "/home/airflow/.local/lib/python3.12/site-packages/mlflow/utils/file_utils.py", line 214, in mkdir
    raise e
  File "/home/airflow/.local/lib/python3.12/site-packages/mlflow/utils/file_utils.py", line 211, in mkdir
    os.makedirs(target, exist_ok=True)
  File "<frozen os>", line 225, in makedirs
PermissionError: [Errno 13] Permission denied: '../mlruns'
[2024-07-21T08:59:59.986+0000] {taskinstance.py:1206} INFO - Marking task as UP_FOR_RETRY. dag_id=churn_model_DAG, task_id=model_training, run_id=scheduled__2024-07-20T00:00:00+00:00, execution_date=20240720T000000, start_date=20240721T085959, end_date=20240721T085959
[2024-07-21T09:00:00.002+0000] {standard_task_runner.py:110} ERROR - Failed to execute job 466 for task model_training ([Errno 13] Permission denied: '../mlruns'; 545)
[2024-07-21T09:00:00.035+0000] {local_task_job_runner.py:243} INFO - Task exited with return code 1
[2024-07-21T09:00:00.058+0000] {taskinstance.py:3503} INFO - 0 downstream tasks scheduled from follow-on schedule check
[2024-07-21T09:00:00.059+0000] {local_task_job_runner.py:222} INFO - ::endgroup::
[2024-07-21T09:01:32.219+0000] {local_task_job_runner.py:120} INFO - ::group::Pre task execution logs
[2024-07-21T09:01:32.232+0000] {taskinstance.py:2076} INFO - Dependencies all met for dep_context=non-requeueable deps ti=<TaskInstance: churn_model_DAG.model_training scheduled__2024-07-20T00:00:00+00:00 [queued]>
[2024-07-21T09:01:32.345+0000] {taskinstance.py:2076} INFO - Dependencies all met for dep_context=requeueable deps ti=<TaskInstance: churn_model_DAG.model_training scheduled__2024-07-20T00:00:00+00:00 [queued]>
[2024-07-21T09:01:32.345+0000] {taskinstance.py:2306} INFO - Starting attempt 1 of 2
[2024-07-21T09:01:32.351+0000] {taskinstance.py:2330} INFO - Executing <Task(PythonOperator): model_training> on 2024-07-20 00:00:00+00:00
[2024-07-21T09:01:32.362+0000] {warnings.py:112} WARNING - /home/***/.local/lib/python3.12/site-packages/***/task/task_runner/standard_task_runner.py:62: DeprecationWarning: This process (pid=598) is multi-threaded, use of fork() may lead to deadlocks in the child.
  pid = os.fork()

[2024-07-21T09:01:32.365+0000] {standard_task_runner.py:64} INFO - Started process 607 to run task
[2024-07-21T09:01:32.363+0000] {standard_task_runner.py:90} INFO - Running: ['***', 'tasks', 'run', 'churn_model_DAG', 'model_training', 'scheduled__2024-07-20T00:00:00+00:00', '--job-id', '468', '--raw', '--subdir', 'DAGS_FOLDER/model_pipeline_DAG.py', '--cfg-path', '/tmp/tmpmpscbu5s']
[2024-07-21T09:01:32.369+0000] {standard_task_runner.py:91} INFO - Job 468: Subtask model_training
[2024-07-21T09:01:32.413+0000] {task_command.py:426} INFO - Running <TaskInstance: churn_model_DAG.model_training scheduled__2024-07-20T00:00:00+00:00 [running]> on host 6e10856c4017
[2024-07-21T09:01:32.489+0000] {taskinstance.py:2648} INFO - Exporting env vars: AIRFLOW_CTX_DAG_OWNER='***' AIRFLOW_CTX_DAG_ID='churn_model_DAG' AIRFLOW_CTX_TASK_ID='model_training' AIRFLOW_CTX_EXECUTION_DATE='2024-07-20T00:00:00+00:00' AIRFLOW_CTX_TRY_NUMBER='1' AIRFLOW_CTX_DAG_RUN_ID='scheduled__2024-07-20T00:00:00+00:00'
[2024-07-21T09:01:32.490+0000] {taskinstance.py:430} INFO - ::endgroup::
[2024-07-21T09:01:32.955+0000] {logging_mixin.py:188} WARNING - 2024/07/21 09:01:32 WARNING mlflow.utils.git_utils: Failed to import Git (the Git executable is probably not on your PATH), so Git SHA is not available. Error: Failed to initialize: Bad git executable.
The git executable must be specified in one of the following ways:
    - be included in your $PATH
    - be set via $GIT_PYTHON_GIT_EXECUTABLE
    - explicitly set via git.refresh(<full-path-to-git-executable>)

All git commands will error until this is rectified.

This initial message can be silenced or aggravated in the future by setting the
$GIT_PYTHON_REFRESH environment variable. Use one of the following values:
    - quiet|q|silence|s|silent|none|n|0: for no message or exception
    - warn|w|warning|log|l|1: for a warning message (logging level CRITICAL, displayed by default)
    - error|e|exception|raise|r|2: for a raised exception

Example:
    export GIT_PYTHON_REFRESH=quiet
[2024-07-21T09:05:48.115+0000] {logging_mixin.py:188} INFO - Run completed!
[2024-07-21T09:05:48.118+0000] {python.py:237} INFO - Done. Returned value was: None
[2024-07-21T09:05:48.124+0000] {taskinstance.py:441} INFO - ::group::Post task execution logs
[2024-07-21T09:05:48.147+0000] {taskinstance.py:1206} INFO - Marking task as SUCCESS. dag_id=churn_model_DAG, task_id=model_training, run_id=scheduled__2024-07-20T00:00:00+00:00, execution_date=20240720T000000, start_date=20240721T090132, end_date=20240721T090548
[2024-07-21T09:05:48.213+0000] {local_task_job_runner.py:243} INFO - Task exited with return code 0
[2024-07-21T09:05:48.236+0000] {taskinstance.py:3503} INFO - 0 downstream tasks scheduled from follow-on schedule check
[2024-07-21T09:05:48.236+0000] {local_task_job_runner.py:222} INFO - ::endgroup::
