[2024-07-21T09:25:04.845+0000] {local_task_job_runner.py:120} INFO - ::group::Pre task execution logs
[2024-07-21T09:25:04.932+0000] {taskinstance.py:2076} INFO - Dependencies all met for dep_context=non-requeueable deps ti=<TaskInstance: churn_model_DAG.model_training manual__2024-07-21T09:24:56.478895+00:00 [queued]>
[2024-07-21T09:25:04.936+0000] {taskinstance.py:2076} INFO - Dependencies all met for dep_context=requeueable deps ti=<TaskInstance: churn_model_DAG.model_training manual__2024-07-21T09:24:56.478895+00:00 [queued]>
[2024-07-21T09:25:04.936+0000] {taskinstance.py:2306} INFO - Starting attempt 1 of 2
[2024-07-21T09:25:04.943+0000] {taskinstance.py:2330} INFO - Executing <Task(PythonOperator): model_training> on 2024-07-21 09:24:56.478895+00:00
[2024-07-21T09:25:04.947+0000] {warnings.py:112} WARNING - /home/***/.local/lib/python3.12/site-packages/***/task/task_runner/standard_task_runner.py:62: DeprecationWarning: This process (pid=1335) is multi-threaded, use of fork() may lead to deadlocks in the child.
  pid = os.fork()

[2024-07-21T09:25:04.949+0000] {standard_task_runner.py:64} INFO - Started process 1344 to run task
[2024-07-21T09:25:04.949+0000] {standard_task_runner.py:90} INFO - Running: ['***', 'tasks', 'run', 'churn_model_DAG', 'model_training', 'manual__2024-07-21T09:24:56.478895+00:00', '--job-id', '475', '--raw', '--subdir', 'DAGS_FOLDER/model_pipeline_DAG.py', '--cfg-path', '/tmp/tmp1hugxwjm']
[2024-07-21T09:25:04.950+0000] {standard_task_runner.py:91} INFO - Job 475: Subtask model_training
[2024-07-21T09:25:04.974+0000] {task_command.py:426} INFO - Running <TaskInstance: churn_model_DAG.model_training manual__2024-07-21T09:24:56.478895+00:00 [running]> on host 6e10856c4017
[2024-07-21T09:25:05.021+0000] {taskinstance.py:2648} INFO - Exporting env vars: AIRFLOW_CTX_DAG_OWNER='***' AIRFLOW_CTX_DAG_ID='churn_model_DAG' AIRFLOW_CTX_TASK_ID='model_training' AIRFLOW_CTX_EXECUTION_DATE='2024-07-21T09:24:56.478895+00:00' AIRFLOW_CTX_TRY_NUMBER='1' AIRFLOW_CTX_DAG_RUN_ID='manual__2024-07-21T09:24:56.478895+00:00'
[2024-07-21T09:25:05.022+0000] {taskinstance.py:430} INFO - ::endgroup::
[2024-07-21T09:25:05.409+0000] {logging_mixin.py:188} WARNING - 2024/07/21 09:25:05 WARNING mlflow.utils.git_utils: Failed to import Git (the Git executable is probably not on your PATH), so Git SHA is not available. Error: Failed to initialize: Bad git executable.
The git executable must be specified in one of the following ways:
    - be included in your $PATH
    - be set via $GIT_PYTHON_GIT_EXECUTABLE
    - explicitly set via git.refresh(<full-path-to-git-executable>)

All git commands will error until this is rectified.

This initial message can be silenced or aggravated in the future by setting the
$GIT_PYTHON_REFRESH environment variable. Use one of the following values:
    - quiet|q|silence|s|silent|none|n|0: for no message or exception
    - warn|w|warning|log|l|1: for a warning message (logging level CRITICAL, displayed by default)
    - error|e|exception|raise|r|2: for a raised exception

Example:
    export GIT_PYTHON_REFRESH=quiet
[2024-07-21T09:25:05.411+0000] {taskinstance.py:441} INFO - ::group::Post task execution logs
[2024-07-21T09:25:05.412+0000] {taskinstance.py:2905} ERROR - Task failed with exception
Traceback (most recent call last):
  File "/home/airflow/.local/lib/python3.12/site-packages/airflow/models/taskinstance.py", line 465, in _execute_task
    result = _execute_callable(context=context, **execute_callable_kwargs)
             ^^^^^^^^^^^^^^^^^^^^^^^^^^^^^^^^^^^^^^^^^^^^^^^^^^^^^^^^^^^^^
  File "/home/airflow/.local/lib/python3.12/site-packages/airflow/models/taskinstance.py", line 432, in _execute_callable
    return execute_callable(context=context, **execute_callable_kwargs)
           ^^^^^^^^^^^^^^^^^^^^^^^^^^^^^^^^^^^^^^^^^^^^^^^^^^^^^^^^^^^^
  File "/home/airflow/.local/lib/python3.12/site-packages/airflow/models/baseoperator.py", line 401, in wrapper
    return func(self, *args, **kwargs)
           ^^^^^^^^^^^^^^^^^^^^^^^^^^^
  File "/home/airflow/.local/lib/python3.12/site-packages/airflow/operators/python.py", line 235, in execute
    return_value = self.execute_callable()
                   ^^^^^^^^^^^^^^^^^^^^^^^
  File "/home/airflow/.local/lib/python3.12/site-packages/airflow/operators/python.py", line 252, in execute_callable
    return self.python_callable(*self.op_args, **self.op_kwargs)
           ^^^^^^^^^^^^^^^^^^^^^^^^^^^^^^^^^^^^^^^^^^^^^^^^^^^^^
  File "/opt/airflow/dags/model_pipeline_DAG.py", line 34, in run_model_training
    trainer.train_and_evaluate()
  File "/opt/airflow/dags/model_train.py", line 68, in train_and_evaluate
    with mlflow.start_run():
         ^^^^^^^^^^^^^^^^^^
  File "/home/airflow/.local/lib/python3.12/site-packages/mlflow/tracking/fluent.py", line 382, in start_run
    active_run_obj = client.create_run(
                     ^^^^^^^^^^^^^^^^^^
  File "/home/airflow/.local/lib/python3.12/site-packages/mlflow/tracking/client.py", line 393, in create_run
    return self._tracking_client.create_run(experiment_id, start_time, tags, run_name)
           ^^^^^^^^^^^^^^^^^^^^^^^^^^^^^^^^^^^^^^^^^^^^^^^^^^^^^^^^^^^^^^^^^^^^^^^^^^^
  File "/home/airflow/.local/lib/python3.12/site-packages/mlflow/tracking/_tracking_service/client.py", line 165, in create_run
    return self.store.create_run(
           ^^^^^^^^^^^^^^^^^^^^^^
  File "/home/airflow/.local/lib/python3.12/site-packages/mlflow/store/tracking/file_store.py", line 623, in create_run
    experiment = self.get_experiment(experiment_id)
                 ^^^^^^^^^^^^^^^^^^^^^^^^^^^^^^^^^^
  File "/home/airflow/.local/lib/python3.12/site-packages/mlflow/store/tracking/file_store.py", line 436, in get_experiment
    experiment = self._get_experiment(experiment_id)
                 ^^^^^^^^^^^^^^^^^^^^^^^^^^^^^^^^^^^
  File "/home/airflow/.local/lib/python3.12/site-packages/mlflow/store/tracking/file_store.py", line 406, in _get_experiment
    raise MlflowException(
mlflow.exceptions.MlflowException: Could not find experiment with ID 318779206120265020
[2024-07-21T09:25:05.422+0000] {taskinstance.py:1206} INFO - Marking task as UP_FOR_RETRY. dag_id=churn_model_DAG, task_id=model_training, run_id=manual__2024-07-21T09:24:56.478895+00:00, execution_date=20240721T092456, start_date=20240721T092504, end_date=20240721T092505
[2024-07-21T09:25:05.429+0000] {standard_task_runner.py:110} ERROR - Failed to execute job 475 for task model_training (Could not find experiment with ID 318779206120265020; 1344)
[2024-07-21T09:25:05.466+0000] {local_task_job_runner.py:243} INFO - Task exited with return code 1
[2024-07-21T09:25:05.480+0000] {taskinstance.py:3503} INFO - 0 downstream tasks scheduled from follow-on schedule check
[2024-07-21T09:25:05.481+0000] {local_task_job_runner.py:222} INFO - ::endgroup::
