[2024-07-21T09:19:21.796+0000] {local_task_job_runner.py:120} INFO - ::group::Pre task execution logs
[2024-07-21T09:19:22.048+0000] {taskinstance.py:2076} INFO - Dependencies all met for dep_context=non-requeueable deps ti=<TaskInstance: churn_model_DAG.model_training manual__2024-07-21T09:19:12.913313+00:00 [queued]>
[2024-07-21T09:19:22.054+0000] {taskinstance.py:2076} INFO - Dependencies all met for dep_context=requeueable deps ti=<TaskInstance: churn_model_DAG.model_training manual__2024-07-21T09:19:12.913313+00:00 [queued]>
[2024-07-21T09:19:22.054+0000] {taskinstance.py:2306} INFO - Starting attempt 1 of 2
[2024-07-21T09:19:22.063+0000] {taskinstance.py:2330} INFO - Executing <Task(PythonOperator): model_training> on 2024-07-21 09:19:12.913313+00:00
[2024-07-21T09:19:22.088+0000] {warnings.py:112} WARNING - /home/***/.local/lib/python3.12/site-packages/***/task/task_runner/standard_task_runner.py:62: DeprecationWarning: This process (pid=1150) is multi-threaded, use of fork() may lead to deadlocks in the child.
  pid = os.fork()

[2024-07-21T09:19:22.100+0000] {standard_task_runner.py:64} INFO - Started process 1159 to run task
[2024-07-21T09:19:22.093+0000] {standard_task_runner.py:90} INFO - Running: ['***', 'tasks', 'run', 'churn_model_DAG', 'model_training', 'manual__2024-07-21T09:19:12.913313+00:00', '--job-id', '472', '--raw', '--subdir', 'DAGS_FOLDER/model_pipeline_DAG.py', '--cfg-path', '/tmp/tmpckqa30up']
[2024-07-21T09:19:22.104+0000] {standard_task_runner.py:91} INFO - Job 472: Subtask model_training
[2024-07-21T09:19:22.151+0000] {task_command.py:426} INFO - Running <TaskInstance: churn_model_DAG.model_training manual__2024-07-21T09:19:12.913313+00:00 [running]> on host 6e10856c4017
[2024-07-21T09:19:22.318+0000] {taskinstance.py:2648} INFO - Exporting env vars: AIRFLOW_CTX_DAG_OWNER='***' AIRFLOW_CTX_DAG_ID='churn_model_DAG' AIRFLOW_CTX_TASK_ID='model_training' AIRFLOW_CTX_EXECUTION_DATE='2024-07-21T09:19:12.913313+00:00' AIRFLOW_CTX_TRY_NUMBER='1' AIRFLOW_CTX_DAG_RUN_ID='manual__2024-07-21T09:19:12.913313+00:00'
[2024-07-21T09:19:22.319+0000] {taskinstance.py:430} INFO - ::endgroup::
[2024-07-21T09:19:22.716+0000] {logging_mixin.py:188} WARNING - 2024/07/21 09:19:22 WARNING mlflow.utils.git_utils: Failed to import Git (the Git executable is probably not on your PATH), so Git SHA is not available. Error: Failed to initialize: Bad git executable.
The git executable must be specified in one of the following ways:
    - be included in your $PATH
    - be set via $GIT_PYTHON_GIT_EXECUTABLE
    - explicitly set via git.refresh(<full-path-to-git-executable>)

All git commands will error until this is rectified.

This initial message can be silenced or aggravated in the future by setting the
$GIT_PYTHON_REFRESH environment variable. Use one of the following values:
    - quiet|q|silence|s|silent|none|n|0: for no message or exception
    - warn|w|warning|log|l|1: for a warning message (logging level CRITICAL, displayed by default)
    - error|e|exception|raise|r|2: for a raised exception

Example:
    export GIT_PYTHON_REFRESH=quiet
[2024-07-21T09:19:22.791+0000] {connectionpool.py:872} WARNING - Retrying (Retry(total=4, connect=4, read=5, redirect=5, status=5)) after connection broken by 'NameResolutionError("<urllib3.connection.HTTPConnection object at 0xffff92d67ce0>: Failed to resolve 'mlflow' ([Errno -2] Name or service not known)")': /api/2.0/mlflow/runs/create
[2024-07-21T09:19:27.047+0000] {connectionpool.py:872} WARNING - Retrying (Retry(total=3, connect=3, read=5, redirect=5, status=5)) after connection broken by 'NameResolutionError("<urllib3.connection.HTTPConnection object at 0xffff92ad5fd0>: Failed to resolve 'mlflow' ([Errno -2] Name or service not known)")': /api/2.0/mlflow/runs/create
[2024-07-21T09:19:35.598+0000] {connectionpool.py:872} WARNING - Retrying (Retry(total=2, connect=2, read=5, redirect=5, status=5)) after connection broken by 'NameResolutionError("<urllib3.connection.HTTPConnection object at 0xffff92ad66f0>: Failed to resolve 'mlflow' ([Errno -2] Name or service not known)")': /api/2.0/mlflow/runs/create
[2024-07-21T09:19:51.796+0000] {connectionpool.py:872} WARNING - Retrying (Retry(total=1, connect=1, read=5, redirect=5, status=5)) after connection broken by 'NameResolutionError("<urllib3.connection.HTTPConnection object at 0xffff92ad6ea0>: Failed to resolve 'mlflow' ([Errno -2] Name or service not known)")': /api/2.0/mlflow/runs/create
[2024-07-21T09:20:24.652+0000] {connectionpool.py:872} WARNING - Retrying (Retry(total=0, connect=0, read=5, redirect=5, status=5)) after connection broken by 'NameResolutionError("<urllib3.connection.HTTPConnection object at 0xffff92ad7020>: Failed to resolve 'mlflow' ([Errno -2] Name or service not known)")': /api/2.0/mlflow/runs/create
[2024-07-21T09:20:24.673+0000] {taskinstance.py:441} INFO - ::group::Post task execution logs
[2024-07-21T09:20:24.677+0000] {taskinstance.py:2905} ERROR - Task failed with exception
Traceback (most recent call last):
  File "/home/airflow/.local/lib/python3.12/site-packages/urllib3/connection.py", line 203, in _new_conn
    sock = connection.create_connection(
           ^^^^^^^^^^^^^^^^^^^^^^^^^^^^^
  File "/home/airflow/.local/lib/python3.12/site-packages/urllib3/util/connection.py", line 60, in create_connection
    for res in socket.getaddrinfo(host, port, family, socket.SOCK_STREAM):
               ^^^^^^^^^^^^^^^^^^^^^^^^^^^^^^^^^^^^^^^^^^^^^^^^^^^^^^^^^^
  File "/usr/local/lib/python3.12/socket.py", line 964, in getaddrinfo
    for res in _socket.getaddrinfo(host, port, family, type, proto, flags):
               ^^^^^^^^^^^^^^^^^^^^^^^^^^^^^^^^^^^^^^^^^^^^^^^^^^^^^^^^^^^
socket.gaierror: [Errno -2] Name or service not known

The above exception was the direct cause of the following exception:

Traceback (most recent call last):
  File "/home/airflow/.local/lib/python3.12/site-packages/urllib3/connectionpool.py", line 791, in urlopen
    response = self._make_request(
               ^^^^^^^^^^^^^^^^^^^
  File "/home/airflow/.local/lib/python3.12/site-packages/urllib3/connectionpool.py", line 497, in _make_request
    conn.request(
  File "/home/airflow/.local/lib/python3.12/site-packages/urllib3/connection.py", line 395, in request
    self.endheaders()
  File "/usr/local/lib/python3.12/http/client.py", line 1331, in endheaders
    self._send_output(message_body, encode_chunked=encode_chunked)
  File "/usr/local/lib/python3.12/http/client.py", line 1091, in _send_output
    self.send(msg)
  File "/usr/local/lib/python3.12/http/client.py", line 1035, in send
    self.connect()
  File "/home/airflow/.local/lib/python3.12/site-packages/urllib3/connection.py", line 243, in connect
    self.sock = self._new_conn()
                ^^^^^^^^^^^^^^^^
  File "/home/airflow/.local/lib/python3.12/site-packages/urllib3/connection.py", line 210, in _new_conn
    raise NameResolutionError(self.host, self, e) from e
urllib3.exceptions.NameResolutionError: <urllib3.connection.HTTPConnection object at 0xffff92ad7770>: Failed to resolve 'mlflow' ([Errno -2] Name or service not known)

The above exception was the direct cause of the following exception:

Traceback (most recent call last):
  File "/home/airflow/.local/lib/python3.12/site-packages/requests/adapters.py", line 667, in send
    resp = conn.urlopen(
           ^^^^^^^^^^^^^
  File "/home/airflow/.local/lib/python3.12/site-packages/urllib3/connectionpool.py", line 875, in urlopen
    return self.urlopen(
           ^^^^^^^^^^^^^
  File "/home/airflow/.local/lib/python3.12/site-packages/urllib3/connectionpool.py", line 875, in urlopen
    return self.urlopen(
           ^^^^^^^^^^^^^
  File "/home/airflow/.local/lib/python3.12/site-packages/urllib3/connectionpool.py", line 875, in urlopen
    return self.urlopen(
           ^^^^^^^^^^^^^
  [Previous line repeated 2 more times]
  File "/home/airflow/.local/lib/python3.12/site-packages/urllib3/connectionpool.py", line 845, in urlopen
    retries = retries.increment(
              ^^^^^^^^^^^^^^^^^^
  File "/home/airflow/.local/lib/python3.12/site-packages/urllib3/util/retry.py", line 515, in increment
    raise MaxRetryError(_pool, url, reason) from reason  # type: ignore[arg-type]
    ^^^^^^^^^^^^^^^^^^^^^^^^^^^^^^^^^^^^^^^^^^^^^^^^^^^
urllib3.exceptions.MaxRetryError: HTTPConnectionPool(host='mlflow', port=5000): Max retries exceeded with url: /api/2.0/mlflow/runs/create (Caused by NameResolutionError("<urllib3.connection.HTTPConnection object at 0xffff92ad7770>: Failed to resolve 'mlflow' ([Errno -2] Name or service not known)"))

During handling of the above exception, another exception occurred:

Traceback (most recent call last):
  File "/home/airflow/.local/lib/python3.12/site-packages/mlflow/utils/rest_utils.py", line 129, in http_request
    return _get_http_response_with_retries(
           ^^^^^^^^^^^^^^^^^^^^^^^^^^^^^^^^
  File "/home/airflow/.local/lib/python3.12/site-packages/mlflow/utils/request_utils.py", line 237, in _get_http_response_with_retries
    return session.request(method, url, allow_redirects=allow_redirects, **kwargs)
           ^^^^^^^^^^^^^^^^^^^^^^^^^^^^^^^^^^^^^^^^^^^^^^^^^^^^^^^^^^^^^^^^^^^^^^^
  File "/home/airflow/.local/lib/python3.12/site-packages/requests/sessions.py", line 589, in request
    resp = self.send(prep, **send_kwargs)
           ^^^^^^^^^^^^^^^^^^^^^^^^^^^^^^
  File "/home/airflow/.local/lib/python3.12/site-packages/requests/sessions.py", line 703, in send
    r = adapter.send(request, **kwargs)
        ^^^^^^^^^^^^^^^^^^^^^^^^^^^^^^^
  File "/home/airflow/.local/lib/python3.12/site-packages/requests/adapters.py", line 700, in send
    raise ConnectionError(e, request=request)
requests.exceptions.ConnectionError: HTTPConnectionPool(host='mlflow', port=5000): Max retries exceeded with url: /api/2.0/mlflow/runs/create (Caused by NameResolutionError("<urllib3.connection.HTTPConnection object at 0xffff92ad7770>: Failed to resolve 'mlflow' ([Errno -2] Name or service not known)"))

During handling of the above exception, another exception occurred:

Traceback (most recent call last):
  File "/home/airflow/.local/lib/python3.12/site-packages/airflow/models/taskinstance.py", line 465, in _execute_task
    result = _execute_callable(context=context, **execute_callable_kwargs)
             ^^^^^^^^^^^^^^^^^^^^^^^^^^^^^^^^^^^^^^^^^^^^^^^^^^^^^^^^^^^^^
  File "/home/airflow/.local/lib/python3.12/site-packages/airflow/models/taskinstance.py", line 432, in _execute_callable
    return execute_callable(context=context, **execute_callable_kwargs)
           ^^^^^^^^^^^^^^^^^^^^^^^^^^^^^^^^^^^^^^^^^^^^^^^^^^^^^^^^^^^^
  File "/home/airflow/.local/lib/python3.12/site-packages/airflow/models/baseoperator.py", line 401, in wrapper
    return func(self, *args, **kwargs)
           ^^^^^^^^^^^^^^^^^^^^^^^^^^^
  File "/home/airflow/.local/lib/python3.12/site-packages/airflow/operators/python.py", line 235, in execute
    return_value = self.execute_callable()
                   ^^^^^^^^^^^^^^^^^^^^^^^
  File "/home/airflow/.local/lib/python3.12/site-packages/airflow/operators/python.py", line 252, in execute_callable
    return self.python_callable(*self.op_args, **self.op_kwargs)
           ^^^^^^^^^^^^^^^^^^^^^^^^^^^^^^^^^^^^^^^^^^^^^^^^^^^^^
  File "/opt/airflow/dags/model_pipeline_DAG.py", line 34, in run_model_training
    trainer.train_and_evaluate()
  File "/opt/airflow/dags/model_train.py", line 68, in train_and_evaluate
    with mlflow.start_run():
         ^^^^^^^^^^^^^^^^^^
  File "/home/airflow/.local/lib/python3.12/site-packages/mlflow/tracking/fluent.py", line 382, in start_run
    active_run_obj = client.create_run(
                     ^^^^^^^^^^^^^^^^^^
  File "/home/airflow/.local/lib/python3.12/site-packages/mlflow/tracking/client.py", line 393, in create_run
    return self._tracking_client.create_run(experiment_id, start_time, tags, run_name)
           ^^^^^^^^^^^^^^^^^^^^^^^^^^^^^^^^^^^^^^^^^^^^^^^^^^^^^^^^^^^^^^^^^^^^^^^^^^^
  File "/home/airflow/.local/lib/python3.12/site-packages/mlflow/tracking/_tracking_service/client.py", line 165, in create_run
    return self.store.create_run(
           ^^^^^^^^^^^^^^^^^^^^^^
  File "/home/airflow/.local/lib/python3.12/site-packages/mlflow/store/tracking/rest_store.py", line 208, in create_run
    response_proto = self._call_endpoint(CreateRun, req_body)
                     ^^^^^^^^^^^^^^^^^^^^^^^^^^^^^^^^^^^^^^^^
  File "/home/airflow/.local/lib/python3.12/site-packages/mlflow/store/tracking/rest_store.py", line 81, in _call_endpoint
    return call_endpoint(self.get_host_creds(), endpoint, method, json_body, response_proto)
           ^^^^^^^^^^^^^^^^^^^^^^^^^^^^^^^^^^^^^^^^^^^^^^^^^^^^^^^^^^^^^^^^^^^^^^^^^^^^^^^^^
  File "/home/airflow/.local/lib/python3.12/site-packages/mlflow/utils/rest_utils.py", line 302, in call_endpoint
    response = http_request(**call_kwargs)
               ^^^^^^^^^^^^^^^^^^^^^^^^^^^
  File "/home/airflow/.local/lib/python3.12/site-packages/mlflow/utils/rest_utils.py", line 152, in http_request
    raise MlflowException(f"API request to {url} failed with exception {e}")
mlflow.exceptions.MlflowException: API request to http://mlflow:5000/api/2.0/mlflow/runs/create failed with exception HTTPConnectionPool(host='mlflow', port=5000): Max retries exceeded with url: /api/2.0/mlflow/runs/create (Caused by NameResolutionError("<urllib3.connection.HTTPConnection object at 0xffff92ad7770>: Failed to resolve 'mlflow' ([Errno -2] Name or service not known)"))
[2024-07-21T09:20:24.712+0000] {taskinstance.py:1206} INFO - Marking task as UP_FOR_RETRY. dag_id=churn_model_DAG, task_id=model_training, run_id=manual__2024-07-21T09:19:12.913313+00:00, execution_date=20240721T091912, start_date=20240721T091922, end_date=20240721T092024
[2024-07-21T09:20:24.727+0000] {standard_task_runner.py:110} ERROR - Failed to execute job 472 for task model_training (API request to http://mlflow:5000/api/2.0/mlflow/runs/create failed with exception HTTPConnectionPool(host='mlflow', port=5000): Max retries exceeded with url: /api/2.0/mlflow/runs/create (Caused by NameResolutionError("<urllib3.connection.HTTPConnection object at 0xffff92ad7770>: Failed to resolve 'mlflow' ([Errno -2] Name or service not known)")); 1159)
[2024-07-21T09:20:24.753+0000] {local_task_job_runner.py:243} INFO - Task exited with return code 1
[2024-07-21T09:20:24.778+0000] {taskinstance.py:3503} INFO - 0 downstream tasks scheduled from follow-on schedule check
[2024-07-21T09:20:24.779+0000] {local_task_job_runner.py:222} INFO - ::endgroup::
